Workbook

Sheet Handicaps
B5: Team | C5: Nombre | D5: Apellido 1 | E5: Apellido 2 | F5: Hcp | G5: Hcp de juego | H5: Licencia | O5: Apellido 1 | P5: actual | Q5: 2025 | R5: diferencia
B6: Loco | C6: Jose Maria | D6: Alonso | E6: Monforte | F6: 12.1 | G6: 15 | H6: CM01158583 | O6: Alonso | P6: 12.1 | Q6: 11.1 | R6: =+P6-Q6 -> 1
B7: Loco | C7: Juan | D7: Bejar | E7: Frias | F7: 14.6 | G7: 18 | H7: CM01280923 | O7: Bejar | P7: 14.6 | Q7: 15.7 | R7: =+P7-Q7 -> -1.1
B8: Loco | C8: Alvaro | D8: de Blas | E8: Albert | F8: 8.7 | G8: 11 | H8: CM11113539 | O8: de Blas | P8: 8.7 | Q8: 9.5 | R8: =+P8-Q8 -> -0.8
B9: Loco | C9: Borja | D9: de Luis | E9: de Blas | F9: 9.1 | G9: 11 | H9: CM02114593 | O9: de Luis | P9: 9.1 | Q9: 10 | R9: =+P9-Q9 -> -0.9
B10: Loco | C10: Agustín | D10: De Miguel | E10: Querejeta | F10: 23.6 | G10: 28 | H10: CM02899987 | O10: Dominguez | P10: 11.4 | Q10: 11.4 | R10: =+P10-Q10 -> 0
B11: Loco | C11: Álvaro | D11: De Nicolás | E11: González | F11: 6.8 | G11: 9 | H11: 0201694163 | O11: Edwards | P11: 11.5 | Q11: 10.9 | R11: =+P11-Q11 -> 0.6
B12: Lobo | C12: Jacobo | D12: Dominguez | E12: Vega-Penichet | F12: 11.4 | G12: 14 | H12: CM01630776 | O12: Fernandez | P12: 23.7 | Q12: 23.7 | R12: =+P12-Q12 -> 0
B13: Lobo | C13: Jorge | D13: Edwards | E13: Bernar | F13: 11.5 | G13: 14 | H13: CM01132862 | O13: Gurpegui | P13: 26.9 | Q13: 25.2 | R13: =+P13-Q13 -> 1.7
B14: Lobo | C14: Diego | D14: Fernandez | E14: Ortiz | F14: 23.7 | G14: 28 | H14: 1119187569 | O14: Herrero | P14: 15.7 | Q14: 15.1 | R14: =+P14-Q14 -> 0.6
B15: Lobo | C15: Ignacio | D15: Gurpegui | E15: Aparicio | F15: 26.9 | G15: 32 | H15: CM52972335 | O15: Goizueta | P15: 9.4 | Q15: 8.2 | R15: =+P15-Q15 -> 1.2
B16: Lobo | C16: Pedro | D16: Goizueta | E16: Hernandez | F16: 9.4 | G16: 12 | H16: CM01142461 | O16: Otegui | P16: 12.2 | R16: =+P16-Q16 -> 12.2
B17: Loco | C17: Iñigo | D17: Glez de Castejon | F17: 16.4 | G17: 20 | H17: CM01100458 | O17: Castejas | P17: 16.4 | R17: =+P17-Q17 -> 16.4
B18: Lobo | C18: José Luis | D18: Herrero | F18: 15.7 | G18: 19 | H18: CM81972335 | O18: Merello | P18: 36 | Q18: 36 | R18: =+P18-Q18 -> 0
B19: Loco | C19: Juan | D19: Melgarejo | E19: Molina | F19: 18.8 | G19: 23 | H19: AM00926120 | O19: De Miguel | Q19: 23.7 | R19: =+P19-Q19 -> -23.7
B20: Loco | C20: Carlos | D20: Merello | F20: 36 | G20: 43 | H20: 7705819953 | O20: Melgarejo | P20: 18.8 | Q20: 17.6 | R20: =+P20-Q20 -> 1.2
B21: Lobo | C21: Otto | D21: Otegui | F21: 12.2 | G21: 15 | H21: CM02062781 | O21: De Nicolás | P21: 6.8 | Q21: 7.1 | R21: =+P21-Q21 -> -0.3
B22: Loco | C22: Alvaro | D22: Prieto | E22: Riera | F22: 11.4 | G22: 14 | H22: AM51140802 | O22: Prieto | P22: 11.4 | Q22: 10.5 | R22: =+P22-Q22 -> 0.9
B23: Lobo | C23: Ignacio | D23: Santos | E23: Gallego | F23: 21.7 | G23: 26 | H23: CM04163293 | O23: Santos | P23: 21.7 | Q23: 21.1 | R23: =+P23-Q23 -> 0.6
B24: Lobo | C24: Juan | D24: Suárez de Lezo | E24: Ferrer | F24: 9 | G24: 11 | H24: CM01182159 | O24: Suárez de Lezo | P24: 9 | Q24: 10 | R24: =+P24-Q24 -> -1
B25: Lobo | C25: Fernando | D25: Suárez de Tangil | E25: Peletier | F25: 16.1 | G25: 19 | H25: 7704811529 | O25: Suárez de Tangil | P25: 16.1 | Q25: 15.5 | R25: =+P25-Q25 -> 0.6

Sheet Resumen
J1: Puntos | M1: Partidos
B2: Team | C2: Locos | D2: Lobos | G2: Jugador | H2: Participaciones | I2: Disputados | J2: Aportados | K2: % | L2: Ganados | M2: Empatados | N2: Perdidos
C3: 8 | D3: 4 | G3: Herrero | H3: =Herrero!$E$7 -> 5 | I3: =Herrero!$E$8 -> 10 | J3: =Herrero!$E$9 -> 6.75 | K3: =+J3/I3 -> 0.675 | L3: =Herrero!$D13 -> 7 | M3: =Herrero!$D14 -> 6 | N3: =Herrero!$D15 -> 2
G4: Juan | H4: =Juan!$E$5 -> 13 | I4: =Juan!$E$6 -> 26 | J4: =Juan!$E$7 -> 16.5 | K4: =+J4/I4 -> 0.63461538 | L4: =Juan!$D11 -> 21 | M4: =Juan!$D12 -> 5 | N4: =Juan!$D13 -> 13
G5: Jacobo | H5: =Jacobo!$E$5 -> 13 | I5: =Jacobo!$E$6 -> 26 | J5: =Jacobo!$E$7 -> 14.75 | K5: =+J5/I5 -> 0.56730769 | L5: =Jacobo!$D$11 -> 18 | M5: =Jacobo!$D$12 -> 9 | N5: =Jacobo!$D$13 -> 12
B6: I RYDER CUP LOCOS vs LOBOS | G6: Jido | H6: =Jido!$E$5 -> 13 | I6: =Jido!$E$6 -> 26 | J6: =Jido!$E$7 -> 14.25 | K6: =+J6/I6 -> 0.54807692 | L6: =Jido!$D$11 -> 18 | M6: =Jido!$D$12 -> 5 | N6: =Jido!$D$13 -> 16
B7: Real Club de Golf de Castiello (Gijón, 2013) | C7: 3.25 | D7: 5.75 | G7: Gurpegui | H7: =Gurpegui!$E$7 -> 5 | I7: =Gurpegui!$E$8 -> 10 | J7: =Gurpegui!$E$9 -> 6.25 | K7: =+J7/I7 -> 0.625 | L7: =Gurpegui!$D$13 -> 10 | M7: =Gurpegui!$E$14 -> 0.066666667 | N7: =Gurpegui!D15 -> 4
B8: II RYDER CUP LOCOS vs LOBOS | G8: Pedro | H8: =Pedro!$E$5 -> 12 | I8: =Pedro!$E$6 -> 24 | J8: =Pedro!$E$7 -> 11.75 | K8: =+J8/I8 -> 0.48958333 | L8: =Pedro!$D11 -> 15 | M8: =Pedro!$D12 -> 7 | N8: =Pedro!$D13 -> 17
B9: Layos Golf (Layos, 2014) | C9: 5 | D9: 7 | G9: Fertxo | H9: =Fertxo!$E$6 -> 12 | I9: =Fertxo!$E$7 -> 24 | J9: =Fertxo!$E$8 -> 10 | K9: =+J9/I9 -> 0.41666667 | L9: =Fertxo!$D12 -> 11 | M9: =Fertxo!$D13 -> 8 | N9: =Fertxo!$D14 -> 17
B10: III RYDER CUP LOCOS vs LOBOS | G10: Marcos | H10: =Marcos!$E$6 -> 12 | I10: =Marcos!$E$7 -> 24 | J10: =Marcos!$E$8 -> 9.5 | K10: =+J10/I10 -> 0.39583333 | L10: =Marcos!$D12 -> 10 | M10: =Marcos!$D13 -> 7 | N10: =Marcos!$D14 -> 18
B11: Club de Golf Las Pinaillas (Villapardillo, 2015) | C11: 7 | D11: 5 | G11: Diego | H11: =Diego!$E$6 -> 12 | I11: =Diego!$E$7 -> 24 | J11: =Diego!$E$8 -> 11.5 | K11: =+J11/I11 -> 0.47916667 | L11: =Diego!$D12 -> 16 | M11: =Diego!$D13 -> 5 | N11: =Diego!$D14 -> 15
B12: IV RYDER CUP LOCOS vs LOBOS | G12: Medina | H12: =Medina!$E$7 -> 7 | I12: =Medina!$E$8 -> 14 | J12: =Medina!$E$9 -> 4.75 | K12: =+J12/I12 -> 0.33928571 | L12: =Medina!$D$13 -> 6 | M12: =Medina!$E$14 -> 0.05 | N12: =Medina!$E$15 -> 0.65
B13: Club de Golf Montecastillo (Jerez de la Frontera, 2016) | C13: 7.75 | D13: 7.25 | G13: Nacho | H13: =Nacho!$E$7 -> 11 | I13: =Nacho!$E$8 -> 22 | J13: =Nacho!$E$9 -> 5 | K13: =+J13/I13 -> 0.22727273 | L13: =Nacho!$D13 -> 6 | M13: =Nacho!$D14 -> 6 | N13: =Nacho!$D15 -> 21
B14: V RYDER CUP LOCOS vs LOBOS
B15: Club de Golf La Galiana (Valencia, 2017) | C15: 8 | D15: 7
B16: VI RYDER CUP LOCOS vs LOBOS | H16: XIII RYDER CUP LOCOS vs LOBOS
B17: Club de Golf Isla de Valedecañas (Valdecañas, 2018) | C17: 8 | D17: 7 | H17: El Saler ( Valencia, 2025) | K17: =+SUM(I19:K23) -> 7.5
B18: VII RYDER CUP LOCOS vs LOBOS | I18: Fourball | J18: Greensome | K18: Individuales
B19: Club de Golf La Manga (La Manga, 2019) | C19: 7.25 | D19: 7.75 | H19: Juan-Herrero | I19: =+Juan!H33 -> 0.5 | J19: =Juan!K33 -> 0.5 | K19: =+Juan!N33+Gurpegui!N29 -> 1
B20: VIII RYDER CUP LOCOS vs LOBOS | H20: Jaki-Jido | I20: =+Jacobo!H33 -> 0.5 | J20: =+Jacobo!K33 -> 0 | K20: =+Jacobo!N33+Jido!N23 -> 1.5
B21: Banco Santander (Madrid, 2020) | C21: 10 | D21: 5 | H21: Fercho Nacho | I21: =+Fertxo!H33 -> 0.25 | J21: =+Fertxo!K33 -> 0.25 | K21: =+Fertxo!N33+Nacho!N33 -> 0
B22: IX RYDER CUP LOCOS vs LOBOS | H22: Pedro-Diego | I22: =+Diego!H33 -> 0.5 | J22: =+Diego!K33 -> 0.5 | K22: =+Diego!N33+Pedro!N33 -> 1
B23: Novo Sancti Petri (Cádiz, 2021) | C23: 10 | D23: 5 | H23: Medina Marcos | I23: =+Marcos!H33 -> 0 | J23: =+Marcos!K33 -> 0 | K23: =+Marcos!N33+Medina!N29 -> 1
B24: X RYDER CUP LOCOS vs LOBOS
B25: Assoufid (Marrakech, 2022) | C25: 8.25 | D25: 6.75 | H25: XII RYDER CUP LOCOS vs LOBOS
B26: XI RYDER CUP LOCOS vs LOBOS | H26: La Faisanera (Segovia, 2024) | K26: =+SUM(I28:K32) -> 8.5
B27: Puerto Sherry (Jerez, 2023) | C27: 8 | D27: 7 | I27: Fourball | J27: Greensome | K27: Individuales
B28: XII RYDER CUP LOCOS vs LOBOS | H28: Juan-Gur | I28: =+Juan!H33 -> 0.5 | J28: =Juan!K33 -> 0.5 | K28: =+Juan!N33+Gurpegui!N29 -> 1
B29: La Faisanera (Segovia, 2024) | C29: 5 | D29: 10 | H29: Fertxo-Nacho | I29: =+Fertxo!H33 -> 0.25 | J29: =+Fertxo!K33 -> 0.25 | K29: =+Fertxo!N33+Nacho!N32 -> 0
B30: XIII RYDER CUP LOCOS vs LOBOS | H30: Medina-Marcos | I30: =+Marcos!H33 -> 0 | J30: =+Marcos!K33 -> 0 | K30: =+Marcos!N33+Medina!N29 -> 1
B31: El Saler ( Valencia, 2025) | C31: 7.5 | D31: 7.5 | H31: Pedro-Diego | I31: =+Diego!H33 -> 0.5 | J31: =+Diego!K33 -> 0.5 | K31: =+Diego!N33+Pedro!N32 -> 2
H32: Jaki-Jido | I32: =+Jido!H33 -> 0.5 | J32: =+Jido!K33 -> 0 | K32: =+Jacobo!N33+Jido!N33 -> 1.5
H34: XI RYDER CUP LOCOS vs LOBOS
H35: Puerto Sherry (Jerez, 2023) | K35: =+SUM(I37:K41) -> 7
I36: Fourball | J36: Greensome | K36: Individuales
H37: Fertxo-Marcos | I37: =Marcos!H31 -> 0.25 | J37: =Marcos!K31 -> 0.25 | K37: =Marcos!N31+Fertxo!N31 -> 1
H38: Pablo M. - Pedro | I38: =Pedro!H31 -> 0 | J38: =Pedro!K31 -> 0 | K38: =+Pedro!N31+Medina!N27 -> 1
H39: Jaki-Jido | I39: =+Jido!H31 -> 0.5 | J39: =+Jido!K31 -> 0 | K39: =+Jido!N31+Jacobo!N31 -> 1
H40: Juan-Gur | I40: =+Juan!H31 -> 0.5 | J40: =+Juan!K31 -> 0 | K40: =+Juan!N31+Gurpegui!N27 -> 2
H41: Nacho - Diego | I41: =+Diego!H31 -> 0.5 | J41: =+Diego!K31 -> 0 | K41: =+Diego!N31+Nacho!N31 -> 0
...

Sheet Marcos
C3: Team | E3: Lobos | G3: Partidos | H3: Ganados | K3: Empatados | N3: Perdidos | Q3: Total
C4: Nombre | E4: Marcos | G4: 2014 | H4: =+COUNTIF($H22:$Q22,"Ganado") -> 1 | K4: =+COUNTIF($H22:$Q22,"Empatado") -> 0 | N4: =+COUNTIF($H22:$Q22,"Perdido") -> 2 | Q4: =+SUM(H4:N4) -> 3
G5: 2015 | H5: =+COUNTIF($H23:$Q23,"Ganado") -> 0 | K5: =+COUNTIF($H23:$Q23,"Empatado") -> 0 | N5: =+COUNTIF($H23:$Q23,"Perdido") -> 3 | Q5: =+SUM(H5:N5) -> 3
C6: Total Participaciones | E6: =+COUNT(G4:G15) -> 12 | G6: 2016 | H6: =+COUNTIF($H24:$Q24,"Ganado") -> 1 | K6: =+COUNTIF($H24:$Q24,"Empatado") -> 2 | N6: =+COUNTIF($H24:$Q24,"Perdido") -> 0 | Q6: =+SUM(H6:N6) -> 3
C7: Puntos Disputados | E7: =+E6*2 -> 24 | G7: 2017 | H7: =+COUNTIF($H25:$Q25,"Ganado") -> 1 | K7: =+COUNTIF($H25:$Q25,"Empatado") -> 0 | N7: =+COUNTIF($H25:$Q25,"Perdido") -> 2 | Q7: =+SUM(H7:N7) -> 3
C8: Puntos Aportados | E8: =+Q34 -> 9.5 | G8: 2018 | H8: =+COUNTIF($H26:$Q26,"Ganado") -> 2 | K8: =+COUNTIF($H26:$Q26,"Empatado") -> 0 | N8: =+COUNTIF($H26:$Q26,"Perdido") -> 1 | Q8: =+SUM(H8:N8) -> 3
C9: Porcentaje Puntos | E9: =+E8/E7 -> 0.39583333 | G9: 2019 | H9: =+COUNTIF($H27:$Q27,"Ganado") -> 0 | K9: =+COUNTIF($H27:$Q27,"Empatado") -> 2 | N9: =+COUNTIF($H27:$Q27,"Perdido") -> 1 | Q9: =+SUM(H9:N9) -> 3
G10: 2020 | H10: =+COUNTIF($H28:$Q28,"Ganado") -> 0 | K10: =+COUNTIF($H28:$Q28,"Empatado") -> 1 | N10: =+COUNTIF($H28:$Q28,"Perdido") -> 2 | Q10: =+SUM(H10:N10) -> 3
C11: Total Partidos Disputados | D11: =+SUM(D12:D14) -> 35 | E11: % | G11: 2021 | H11: =+COUNTIF($H29:$Q29,"Ganado") -> 0 | K11: =+COUNTIF($H29:$Q29,"Empatado") -> 0 | N11: =+COUNTIF($H29:$Q29,"Perdido") -> 3 | Q11: =+SUM(H11:N11) -> 3
C12: Ganados | D12: =+D17+D22+D28 -> 10 | E12: =+D12/D$11 -> 0.28571429 | G12: 2022 | H12: =+COUNTIF($H30:$Q30,"Ganado") -> 3 | K12: =+COUNTIF($H30:$Q30,"Empatado") -> 0 | N12: =+COUNTIF($H30:$Q30,"Perdido") -> 0 | Q12: =+SUM(H12:N12) -> 3
C13: Empatados | D13: =+D18+D23+D29 -> 7 | E13: =+D13/D$11 -> 0.2 | G13: 2023 | H13: =+COUNTIF($H31:$Q31,"Ganado") -> 1 | K13: =+COUNTIF($H31:$Q31,"Empatado") -> 2 | N13: =+COUNTIF($H31:$Q31,"Perdido") -> 0 | Q13: =+SUM(H13:N13) -> 3
C14: Perdidos | D14: =+D19+D24+D30 -> 18 | E14: =+D14/D$11 -> 0.51428571 | G14: 2024 | H14: =+COUNTIF($H32:$Q32,"Ganado") -> 1 | K14: =+COUNTIF($H32:$Q32,"Empatado") -> 0 | N14: =+COUNTIF($H32:$Q32,"Perdido") -> 2 | Q14: =+SUM(H14:N14) -> 3
G15: 2025 | H15: =+COUNTIF($H33:$Q33,"Ganado") -> 0 | K15: =+COUNTIF($H33:$Q33,"Empatado") -> 0 | N15: =+COUNTIF($H33:$Q33,"Perdido") -> 2 | Q15: =+SUM(H15:N15) -> 2
C16: Fourball Disputados | D16: =+SUM(D17:D19) -> 12 | E16: % | G16: Resultado Total | H16: =SUM(H4:H14) -> 10 | K16: =SUM(K4:K14) -> 7 | N16: =SUM(N4:N14) -> 16 | Q16: =SUM(Q4:Q15) -> 35
C17: Ganado | D17: =+COUNTIF($I$21:$I$33,"Ganado") -> 3 | E17: =+D17/D$16 -> 0.25
C18: Empatados | D18: =+COUNTIF($I$21:$I$33,"Empatado") -> 3 | E18: =+D18/D$16 -> 0.25 | G18: Puntos | H18: Fourball | I18: Resultado | J18: Enfrentamiento | K18: Greensome | L18: Resultado | M18: Enfrentamiento | N18: Singles | O18: Resultado | P18: Enfrentamiento | Q18: Total
C19: Perdidos | D19: =+COUNTIF($I$21:$I$33,"Perdido") -> 6 | E19: =+D19/D$16 -> 0.5 | G19: Puntos / Partido | H19: 0.5 | K19: 0.5 | N19: 1
G20: Máximo Disponible | H20: =H19*$E$6 -> 6 | K20: =K19*$E$6 -> 6 | N20: =N19*$E$6 -> 12 | Q20: =+SUM(H20:N20) -> 24
C21: Greesome Disputados | D21: =+SUM(D22:D24) -> 12 | E21: % | G21: 2013 | Q21: =+H21+K21+N21 -> 0
C22: Ganados | D22: =+COUNTIF($L$21:$L$33,"Ganado") -> 2 | E22: =+D22/D$21 -> 0.16666667 | G22: =+G21+1 -> 2014 | H22: 0 | I22: =+IF(H22=0.5,"Ganado",IF(H22=0.25,"Empatado",IF(H22<0.25,"Perdido"))) -> Perdido | J22: Marcos - Jido VS Alon - Bugo | K22: 0 | L22: =+IF(K22=0.5,"Ganado",IF(K22=0.25,"Empatado",IF(K22<0.25,"Perdido"))) -> Perdido | M22: Jido - Marcos VS Alon - Bugo | N22: 1 | O22: =+IF(N22=1,"Ganado",IF(N22=0.5,"Empatado",IF(N22<0.5,"Perdido"))) -> Ganado | P22: Castejas | Q22: =+H22+K22+N22 -> 1
C23: Empatados | D23: =+COUNTIF($L$21:$L$33,"Empatado") -> 3 | E23: =+D23/D$21 -> 0.25 | G23: =+G22+1 -> 2015 | H23: 0 | I23: =+IF(H23=0.5,"Ganado",IF(H23=0.25,"Empatado",IF(H23<0.25,"Perdido"))) -> Perdido | J23: Marcos - Jido VS Dore - Castejas | K23: 0 | L23: =+IF(K23=0.5,"Ganado",IF(K23=0.25,"Empatado",IF(K23<0.25,"Perdido"))) -> Perdido | M23: Marcos - Jido VS Dore - Castejas | N23: 0 | O23: =+IF(N23=1,"Ganado",IF(N23=0.5,"Empatado",IF(N23<0.5,"Perdido"))) -> Perdido | P23: Nico | Q23: =+H23+K23+N23 -> 0
C24: Perdidos | D24: =+COUNTIF($L$21:$L$33,"Perdido") -> 7 | E24: =+D24/D$21 -> 0.58333333 | G24: =+G23+1 -> 2016 | H24: 0.25 | I24: =+IF(H24=0.5,"Ganado",IF(H24=0.25,"Empatado",IF(H24<0.25,"Perdido"))) -> Empatado | J24: Marcos - Armando VS Blasfi - Merello | K24: 0.25 | L24: =+IF(K24=0.5,"Ganado",IF(K24=0.25,"Empatado",IF(K24<0.25,"Perdido"))) -> Empatado | M24: Marcos - Armando VS Blasfi - Merello | N24: 1 | O24: =+IF(N24=1,"Ganado",IF(N24=0.5,"Empatado",IF(N24<0.5,"Perdido"))) -> Ganado | P24: Castejas | Q24: =+H24+K24+N24 -> 1.5
G25: 2017 | H25: 0.5 | I25: =+IF(H25=0.5,"Ganado",IF(H25=0.25,"Empatado",IF(H25<0.25,"Perdido"))) -> Ganado | J25: Marcos - Diego VS Prieto - Castejas | K25: 0 | L25: =+IF(K25=0.5,"Ganado",IF(K25=0.25,"Empatado",IF(K25<0.25,"Perdido"))) -> Perdido | M25: Marcos - Diego VS Prieto - Castejas | N25: 0 | O25: =+IF(N25=1,"Ganado",IF(N25=0.5,"Empatado",IF(N25<0.5,"Perdido"))) -> Perdido | P25: Béjar | Q25: =+H25+K25+N25 -> 0.5
G26: 2018 | H26: 0.5 | I26: =+IF(H26=0.5,"Ganado",IF(H26=0.25,"Empatado",IF(H26<0.25,"Perdido"))) -> Ganado | J26: Marcos - Jaki VS Agus - Nico | K26: 0.5 | L26: =+IF(K26=0.5,"Ganado",IF(K26=0.25,"Empatado",IF(K26<0.25,"Perdido"))) -> Ganado | M26: Marcos - Jaki VS Agus - Nico | N26: 0 | O26: =+IF(N26=1,"Ganado",IF(N26=0.5,"Empatado",IF(N26<0.5,"Perdido"))) -> Perdido | P26: Béjar | Q26: =+H26+K26+N26 -> 1
C27: Individuales Disputados | D27: =+SUM(D28:D30) -> 11 | E27: % | G27: 2019 | H27: 0.25 | I27: =+IF(H27=0.5,"Ganado",IF(H27=0.25,"Empatado",IF(H27<0.25,"Perdido"))) -> Empatado | J27: Marcos- Diego VS Castejas Prieto | K27: 0 | L27: =+IF(K27=0.5,"Ganado",IF(K27=0.25,"Empatado",IF(K27<0.25,"Perdido"))) -> Perdido | M27: Marcos- Diego VS Castejas Prieto | N27: 0.5 | O27: =+IF(N27=1,"Ganado",IF(N27=0.5,"Empatado",IF(N27<0.5,"Perdido"))) -> Empatado | P27: Bejar | Q27: =+H27+K27+N27 -> 0.75
C28: Ganados | D28: =+COUNTIF($O$21:$O$33,"Ganado") -> 5 | E28: =+D28/D$27 -> 0.45454545 | G28: 2020 | H28: 0 | I28: =+IF(H28=0.5,"Ganado",IF(H28=0.25,"Empatado",IF(H28<0.25,"Perdido"))) -> Perdido | J28: Marcos-Fertxo VS Alon Nico | K28: 0.25 | L28: =+IF(K28=0.5,"Ganado",IF(K28=0.25,"Empatado",IF(K28<0.25,"Perdido"))) -> Empatado | M28: Marcos-Fertxo VS Alon Nico | N28: 0 | O28: =+IF(N28=1,"Ganado",IF(N28=0.5,"Empatado",IF(N28<0.5,"Perdido"))) -> Perdido | P28: Béjar | Q28: =+H28+K28+N28 -> 0.25
C29: Empatados | D29: =+COUNTIF($O$21:$O$33,"Empatado") -> 1 | E29: =+D29/D$27 -> 0.090909091 | G29: 2021 | H29: 0 | I29: =+IF(H29=0.5,"Ganado",IF(H29=0.25,"Empatado",IF(H29<0.25,"Perdido"))) -> Perdido | J29: Marcos Jaco VS Cas Prieto | K29: 0 | L29: =+IF(K29=0.5,"Ganado",IF(K29=0.25,"Empatado",IF(K29<0.25,"Perdido"))) -> Perdido | M29: Marcos Jaco VS Cas Prieto | N29: 0 | O29: =+IF(N29=1,"Ganado",IF(N29=0.5,"Empatado",IF(N29<0.5,"Perdido"))) -> Perdido | P29: Blas | Q29: =+H29+K29+N29 -> 0
C30: Perdidos | D30: =+COUNTIF($O$21:$O$33,"Perdido") -> 5 | E30: =+D30/D$27 -> 0.45454545 | G30: 2022 | H30: 0.5 | I30: =+IF(H30=0.5,"Ganado",IF(H30=0.25,"Empatado",IF(H30<0.25,"Perdido"))) -> Ganado | J30: Marcos-Diego VS Béjar-Juanma | K30: 0.5 | L30: =+IF(K30=0.5,"Ganado",IF(K30=0.25,"Empatado",IF(K30<0.25,"Perdido"))) -> Ganado | M30: Marcos-Diego VS Béjar-Juanma | N30: 1 | O30: =+IF(N30=1,"Ganado",IF(N30=0.5,"Empatado",IF(N30<0.5,"Perdido"))) -> Ganado | P30: Agus | Q30: =+H30+K30+N30 -> 2
G31: 2023 | H31: 0.25 | I31: =+IF(H31=0.5,"Ganado",IF(H31=0.25,"Empatado",IF(H31<0.25,"Perdido"))) -> Empatado | J31: Marcos Fertxo VS Nico Bugo | K31: 0.25 | L31: =+IF(K31=0.5,"Ganado",IF(K31=0.25,"Empatado",IF(K31<0.25,"Perdido"))) -> Empatado | M31: Marcos Fertxo VS Nico Bugo | N31: 1 | O31: =+IF(N31=1,"Ganado",IF(N31=0.5,"Empatado",IF(N31<0.5,"Perdido"))) -> Ganado | P31: Pradas | Q31: =+H31+K31+N31 -> 1.5
G32: 2024 | H32: 0 | I32: =+IF(H32=0.5,"Ganado",IF(H32=0.25,"Empatado",IF(H32<0.25,"Perdido"))) -> Perdido | J32: Marcos Medina VS Agus Blasfi | K32: 0 | L32: =+IF(K32=0.5,"Ganado",IF(K32=0.25,"Empatado",IF(K32<0.25,"Perdido"))) -> Perdido | M32: Marcos Medina VS Agus Blasfi | N32: 1 | O32: =+IF(N32=1,"Ganado",IF(N32=0.5,"Empatado",IF(N32<0.5,"Perdido"))) -> Ganado | P32: Agus | Q32: =+H32+K32+N32 -> 1
G33: 2025 | H33: 0 | I33: =+IF(H33=0.5,"Ganado",IF(H33=0.25,"Empatado",IF(H33<0.25,"Perdido"))) -> Perdido | J33: Marcos Medina VS Nico Alon | K33: 0 | L33: =+IF(K33=0.5,"Ganado",IF(K33=0.25,"Empatado",IF(K33<0.25,"Perdido"))) -> Perdido | M33: Marcos Medina VS Nico Alon | Q33: 0
G34: Total | H34: =SUM(H22:H33) -> 2.25 | K34: =SUM(K22:K33) -> 1.75 | N34: =SUM(N22:N33) -> 5.5 | Q34: =SUM(Q21:Q33) -> 9.5

Sheet Juan
C2: Team | E2: Lobos | G2: Partidos | H2: Ganados | K2: Empatados | N2: Perdidos | Q2: Total
C3: Nombre | E3: Juan | G3: 2013 | H3: =+COUNTIF($H21:$Q21,"Ganado") -> 2 | K3: =+COUNTIF($H21:$Q21,"Empatado") -> 0 | N3: =+COUNTIF($H21:$Q21,"Perdido") -> 1 | Q3: =+SUM(H3:N3) -> 3
G4: 2014 | H4: =+COUNTIF($H22:$Q22,"Ganado") -> 1 | K4: =+COUNTIF($H22:$Q22,"Empatado") -> 1 | N4: =+COUNTIF($H22:$Q22,"Perdido") -> 1 | Q4: =+SUM(H4:N4) -> 3
C5: Total Participaciones | E5: =+COUNT(G3:G15) -> 13 | G5: 2015 | H5: =+COUNTIF($H23:$Q23,"Ganado") -> 1 | K5: =+COUNTIF($H23:$Q23,"Empatado") -> 2 | N5: =+COUNTIF($H23:$Q23,"Perdido") -> 0 | Q5: =+SUM(H5:N5) -> 3
C6: Puntos Disputados | E6: =+E5*2 -> 26 | G6: 2016 | H6: =+COUNTIF($H24:$Q24,"Ganado") -> 1 | K6: =+COUNTIF($H24:$Q24,"Empatado") -> 0 | N6: =+COUNTIF($H24:$Q24,"Perdido") -> 2 | Q6: =+SUM(H6:N6) -> 3
C7: Puntos Aportados | E7: =+Q34 -> 16.5 | G7: 2017 | H7: =+COUNTIF($H25:$Q25,"Ganado") -> 1 | K7: =+COUNTIF($H25:$Q25,"Empatado") -> 0 | N7: =+COUNTIF($H25:$Q25,"Perdido") -> 2 | Q7: =+SUM(H7:N7) -> 3
C8: Porcentaje Puntos | E8: =+E7/E6 -> 0.63461538 | G8: 2018 | H8: =+COUNTIF($H26:$Q26,"Ganado") -> 2 | K8: =+COUNTIF($H26:$Q26,"Empatado") -> 0 | N8: =+COUNTIF($H26:$Q26,"Perdido") -> 1 | Q8: =+SUM(H8:N8) -> 3
G9: 2019 | H9: =+COUNTIF($H27:$Q27,"Ganado") -> 2 | K9: =+COUNTIF($H27:$Q27,"Empatado") -> 0 | N9: =+COUNTIF($H27:$Q27,"Perdido") -> 1 | Q9: =+SUM(H9:N9) -> 3
C10: Total Partidos Disputados | D10: =+SUM(D11:D13) -> 39 | E10: % | G10: 2020 | H10: =+COUNTIF($H28:$Q28,"Ganado") -> 1 | K10: =+COUNTIF($H28:$Q28,"Empatado") -> 1 | N10: =+COUNTIF($H28:$Q28,"Perdido") -> 1 | Q10: =+SUM(H10:N10) -> 3
C11: Ganados | D11: =+D16+D21+D26 -> 21 | E11: =+D11/D$10 -> 0.53846154 | G11: 2021 | H11: =+COUNTIF($H29:$Q29,"Ganado") -> 2 | K11: =+COUNTIF($H29:$Q29,"Empatado") -> 0 | N11: =+COUNTIF($H29:$Q29,"Perdido") -> 1 | Q11: =+SUM(H11:N11) -> 3
C12: Empatados | D12: =+D17+D22+D27 -> 5 | E12: =+D12/D$10 -> 0.12820513 | G12: 2022 | H12: =+COUNTIF($H30:$Q30,"Ganado") -> 2 | K12: =+COUNTIF($H30:$Q30,"Empatado") -> 0 | N12: =+COUNTIF($H30:$Q30,"Perdido") -> 1 | Q12: =+SUM(H12:N12) -> 3
C13: Perdidos | D13: =+D18+D23+D28 -> 13 | E13: =+D13/D$10 -> 0.33333333 | G13: 2023 | H13: =+COUNTIF($H31:$Q31,"Ganado") -> 2 | K13: =+COUNTIF($H31:$Q31,"Empatado") -> 0 | N13: =+COUNTIF($H31:$Q31,"Perdido") -> 1 | Q13: =+SUM(H13:N13) -> 3
G14: 2024 | H14: =+COUNTIF($H32:$Q32,"Ganado") -> 2 | K14: =+COUNTIF($H32:$Q32,"Empatado") -> 1 | N14: =+COUNTIF($H32:$Q32,"Perdido") -> 0 | Q14: =+SUM(H14:N14) -> 3
C15: Fourball Disputados | D15: =+SUM(D16:D18) -> 13 | E15: % | G15: 2025 | H15: =+COUNTIF($H33:$Q33,"Ganado") -> 2 | K15: =+COUNTIF($H33:$Q33,"Empatado") -> 0 | N15: =+COUNTIF($H33:$Q33,"Perdido") -> 1 | Q15: =+SUM(H15:N15) -> 3
C16: Ganado | D16: =+COUNTIF($I$21:$I$33,"Ganado") -> 6 | E16: =+D16/D$15 -> 0.46153846 | G16: Resultado Total | H16: =SUM(H3:H14) -> 19 | K16: =SUM(K3:K14) -> 5 | N16: =SUM(N3:N14) -> 12 | Q16: =SUM(Q3:Q14) -> 36
C17: Empatados | D17: =+COUNTIF($I$21:$I$33,"Empatado") -> 2 | E17: =+D17/D$15 -> 0.15384615
C18: Perdidos | D18: =+COUNTIF($I$21:$I$33,"Perdido") -> 5 | E18: =+D18/D$15 -> 0.38461538 | G18: Puntos | H18: Fourball | I18: Resultado | J18: Enfrentamiento | K18: Greensome | L18: Resultado | M18: Enfrentamiento | N18: Singles | O18: Resultado | P18: Enfrentamiento | Q18: Total
G19: Puntos / Partido | H19: 0.5 | K19: 0.5 | N19: 1
C20: Greesome Disputados | D20: =+SUM(D21:D23) -> 13 | E20: % | G20: Máximo Disponible | H20: =H19*$E$5 -> 6.5 | K20: =K19*$E$5 -> 6.5 | N20: =N19*$E$5 -> 13 | Q20: =+SUM(H20:N20) -> 26
C21: Ganados | D21: =+COUNTIF($L$21:$L$33,"Ganado") -> 6 | E21: =+D21/D$20 -> 0.46153846 | G21: 2013 | H21: 0 | I21: =+IF(H21=0.5,"Ganado",IF(H21=0.25,"Empatado",IF(H21<0.25,"Perdido"))) -> Perdido | J21: Juan - Fertxo VS Bugo - Nico | K21: 0.5 | L21: =+IF(K21=0.5,"Ganado",IF(K21=0.25,"Empatado",IF(K21<0.25,"Perdido"))) -> Ganado | M21: Juan - Fertxo VS Bugo - Nico | N21: 1 | O21: =+IF(N21=1,"Ganado",IF(N21=0.5,"Empatado",IF(N21<0.5,"Perdido"))) -> Ganado | P21: Alon | Q21: =+H21+K21+N21 -> 1.5
C22: Empatados | D22: =+COUNTIF($L$21:$L$33,"Empatado") -> 2 | E22: =+D22/D$20 -> 0.15384615 | G22: =+G21+1 -> 2014 | H22: 0 | I22: =+IF(H22=0.5,"Ganado",IF(H22=0.25,"Empatado",IF(H22<0.25,"Perdido"))) -> Perdido | J22: Juan - Fertxo VS Blasfi - Merello | K22: 0.25 | L22: =+IF(K22=0.5,"Ganado",IF(K22=0.25,"Empatado",IF(K22<0.25,"Perdido"))) -> Empatado | M22: Juan - Fertxo VS Blasfi - Merello | N22: 1 | O22: =+IF(N22=1,"Ganado",IF(N22=0.5,"Empatado",IF(N22<0.5,"Perdido"))) -> Ganado | P22: Béjar | Q22: =+H22+K22+N22 -> 1.25
C23: Perdidos | D23: =+COUNTIF($L$21:$L$33,"Perdido") -> 5 | E23: =+D23/D$20 -> 0.38461538 | G23: =+G22+1 -> 2015 | H23: 0.25 | I23: =+IF(H23=0.5,"Ganado",IF(H23=0.25,"Empatado",IF(H23<0.25,"Perdido"))) -> Empatado | J23: Juan - Nacho Vs Bugo - Alon | K23: 0.25 | L23: =+IF(K23=0.5,"Ganado",IF(K23=0.25,"Empatado",IF(K23<0.25,"Perdido"))) -> Empatado | M23: Juan - Nacho Vs Bugo - Alon | N23: 1 | O23: =+IF(N23=1,"Ganado",IF(N23=0.5,"Empatado",IF(N23<0.5,"Perdido"))) -> Ganado | P23: Castejas | Q23: =+H23+K23+N23 -> 1.5
G24: =+G23+1 -> 2016 | H24: 0 | I24: =+IF(H24=0.5,"Ganado",IF(H24=0.25,"Empatado",IF(H24<0.25,"Perdido"))) -> Perdido | J24: Juan - Pedro VS Bugo - Jaime | K24: 0 | L24: =+IF(K24=0.5,"Ganado",IF(K24=0.25,"Empatado",IF(K24<0.25,"Perdido"))) -> Perdido | M24: Juan - Pedro VS Bugo - Jaime | N24: 1 | O24: =+IF(N24=1,"Ganado",IF(N24=0.5,"Empatado",IF(N24<0.5,"Perdido"))) -> Ganado | P24: Dore | Q24: =+H24+K24+N24 -> 1
C25: Individuales Disputados | D25: =+SUM(D26:D28) -> 13 | E25: % | G25: 2017 | H25: 0 | I25: =+IF(H25=0.5,"Ganado",IF(H25=0.25,"Empatado",IF(H25<0.25,"Perdido"))) -> Perdido | J25: Juan - Nacho VS Jaime - Béjar | K25: 0 | L25: =+IF(K25=0.5,"Ganado",IF(K25=0.25,"Empatado",IF(K25<0.25,"Perdido"))) -> Perdido | M25: Juan - Nacho VS Jaime - Béjar | N25: 1 | O25: =+IF(N25=1,"Ganado",IF(N25=0.5,"Empatado",IF(N25<0.5,"Perdido"))) -> Ganado | P25: Dore | Q25: =+H25+K25+N25 -> 1
C26: Ganados | D26: =+COUNTIF($O$21:$O$33,"Ganado") -> 9 | E26: =+D26/D$25 -> 0.69230769 | G26: 2018 | H26: 0.5 | I26: =+IF(H26=0.5,"Ganado",IF(H26=0.25,"Empatado",IF(H26<0.25,"Perdido"))) -> Ganado | J26: Juan- Armando VS Castejas - Prieto | K26: 0 | L26: =+IF(K26=0.5,"Ganado",IF(K26=0.25,"Empatado",IF(K26<0.25,"Perdido"))) -> Perdido | M26: Juan- Armando VS Castejas - Prieto | N26: 1 | O26: =+IF(N26=1,"Ganado",IF(N26=0.5,"Empatado",IF(N26<0.5,"Perdido"))) -> Ganado | P26: Jaime | Q26: =+H26+K26+N26 -> 1.5
C27: Empatados | D27: =+COUNTIF($O$21:$O$33,"Empatado") -> 1 | E27: =+D27/D$25 -> 0.076923077 | G27: 2019 | H27: 0.5 | I27: =+IF(H27=0.5,"Ganado",IF(H27=0.25,"Empatado",IF(H27<0.25,"Perdido"))) -> Ganado | J27: Juan-Pablo G VS Nico-Alon | K27: 0 | L27: =+IF(K27=0.5,"Ganado",IF(K27=0.25,"Empatado",IF(K27<0.25,"Perdido"))) -> Perdido | M27: Juan-Pablo G VS Nico-Alon | N27: 1 | O27: =+IF(N27=1,"Ganado",IF(N27=0.5,"Empatado",IF(N27<0.5,"Perdido"))) -> Ganado | P27: Bugo | Q27: =+H27+K27+N27 -> 1.5
C28: Perdidos | D28: =+COUNTIF($O$21:$O$33,"Perdido") -> 3 | E28: =+D28/D$25 -> 0.23076923 | G28: 2020 | H28: 0 | I28: =+IF(H28=0.5,"Ganado",IF(H28=0.25,"Empatado",IF(H28<0.25,"Perdido"))) -> Perdido | J28: Juan-Pablo M VS Bugo Alf Nico | K28: 0.5 | L28: =+IF(K28=0.5,"Ganado",IF(K28=0.25,"Empatado",IF(K28<0.25,"Perdido"))) -> Ganado | M28: Juan-Pablo M VS Bugo Alf Nico | N28: 0.5 | O28: =+IF(N28=1,"Ganado",IF(N28=0.5,"Empatado",IF(N28<0.5,"Perdido"))) -> Empatado | P28: Alon | Q28: =+H28+K28+N28 -> 1
G29: 2021 | H29: 0.5 | I29: =+IF(H29=0.5,"Ganado",IF(H29=0.25,"Empatado",IF(H29<0.25,"Perdido"))) -> Ganado | J29: Juan- Gupi VS Béjar Agus | K29: 0.5 | L29: =+IF(K29=0.5,"Ganado",IF(K29=0.25,"Empatado",IF(K29<0.25,"Perdido"))) -> Ganado | M29: Juan- Gupi VS Béjar Agus | N29: 0 | O29: =+IF(N29=1,"Ganado",IF(N29=0.5,"Empatado",IF(N29<0.5,"Perdido"))) -> Perdido | P29: Castejas | Q29: =+H29+K29+N29 -> 1
G30: 2022 | H30: 0.5 | I30: =+IF(H30=0.5,"Ganado",IF(H30=0.25,"Empatado",IF(H30<0.25,"Perdido"))) -> Ganado | J30: Juan- Gupi VS Castejas - Prieto | K30: 0.5 | L30: =+IF(K30=0.5,"Ganado",IF(K30=0.25,"Empatado",IF(K30<0.25,"Perdido"))) -> Ganado | M30: Juan- Gupi VS Castejas - Prieto | N30: 0 | O30: =+IF(N30=1,"Ganado",IF(N30=0.5,"Empatado",IF(N30<0.5,"Perdido"))) -> Perdido | P30: Dore | Q30: =+H30+K30+N30 -> 1
G31: 2023 | H31: 0.5 | I31: =+IF(H31=0.5,"Ganado",IF(H31=0.25,"Empatado",IF(H31<0.25,"Perdido"))) -> Ganado | J31: Juan- Gupi VS Castejas - Alon | K31: 0 | L31: =+IF(K31=0.5,"Ganado",IF(K31=0.25,"Empatado",IF(K31<0.25,"Perdido"))) -> Perdido | M31: Juan- Gupi VS Castejas - Alon | N31: 1 | O31: =+IF(N31=1,"Ganado",IF(N31=0.5,"Empatado",IF(N31<0.5,"Perdido"))) -> Ganado | P31: Dore | Q31: =+H31+K31+N31 -> 1.5
G32: 2024 | H32: 0.25 | I32: =+IF(H32=0.5,"Ganado",IF(H32=0.25,"Empatado",IF(H32<0.25,"Perdido"))) -> Empatado | J32: Juan- Gupi VS Nico - Alon | K32: 0.5 | L32: =+IF(K32=0.5,"Ganado",IF(K32=0.25,"Empatado",IF(K32<0.25,"Perdido"))) -> Ganado | M32: Juan- Gupi VS Nico - Alon | N32: 1 | O32: =+IF(N32=1,"Ganado",IF(N32=0.5,"Empatado",IF(N32<0.5,"Perdido"))) -> Ganado | P32: Merello | Q32: =+H32+K32+N32 -> 1.75
G33: 2025 | H33: 0.5 | I33: =+IF(H33=0.5,"Ganado",IF(H33=0.25,"Empatado",IF(H33<0.25,"Perdido"))) -> Ganado | J33: Juan- Herre VS Bugo Pelete | K33: 0.5 | L33: =+IF(K33=0.5,"Ganado",IF(K33=0.25,"Empatado",IF(K33<0.25,"Perdido"))) -> Ganado | M33: Juan- Herre VS Bugo Pelete | N33: 0 | O33: =+IF(N33=1,"Ganado",IF(N33=0.5,"Empatado",IF(N33<0.5,"Perdido"))) -> Perdido | P33: Nico | Q33: =+H33+K33+N33 -> 1
G34: Total | H34: =SUM(H21:H33) -> 3.5 | K34: =SUM(K21:K33) -> 3.5 | N34: =SUM(N21:N33) -> 9.5 | Q34: =SUM(Q21:Q33) -> 16.5

Sheet Diego
C3: Team | E3: Lobos | G3: Partidos | H3: Ganados | K3: Empatados | N3: Perdidos | Q3: Total
C4: Nombre | E4: Diego | G4: 2014 | H4: =+COUNTIF($H22:$Q22,"Ganado") -> 2 | K4: =+COUNTIF($H22:$Q22,"Empatado") -> 0 | N4: =+COUNTIF($H22:$Q22,"Perdido") -> 1 | Q4: =+SUM(H4:N4) -> 3
G5: 2015 | H5: =+COUNTIF($H23:$Q23,"Ganado") -> 0 | K5: =+COUNTIF($H23:$Q23,"Empatado") -> 2 | N5: =+COUNTIF($H23:$Q23,"Perdido") -> 1 | Q5: =+SUM(H5:N5) -> 3
C6: Total Participaciones | E6: =+COUNT(G4:G15) -> 12 | G6: 2016 | H6: =+COUNTIF($H24:$Q24,"Ganado") -> 1 | K6: =+COUNTIF($H24:$Q24,"Empatado") -> 0 | N6: =+COUNTIF($H24:$Q24,"Perdido") -> 2 | Q6: =+SUM(H6:N6) -> 3
C7: Puntos Disputados | E7: =+E6*2 -> 24 | G7: 2017 | H7: =+COUNTIF($H25:$Q25,"Ganado") -> 2 | K7: =+COUNTIF($H25:$Q25,"Empatado") -> 0 | N7: =+COUNTIF($H25:$Q25,"Perdido") -> 1 | Q7: =+SUM(H7:N7) -> 3
C8: Puntos Aportados | E8: =+Q34 -> 11.5 | G8: 2018 | H8: =+COUNTIF($H26:$Q26,"Ganado") -> 1 | K8: =+COUNTIF($H26:$Q26,"Empatado") -> 0 | N8: =+COUNTIF($H26:$Q26,"Perdido") -> 2 | Q8: =+SUM(H8:N8) -> 3
C9: Porcentaje Puntos | E9: =+E8/E7 -> 0.47916667 | G9: 2019 | H9: =+COUNTIF($H27:$Q27,"Ganado") -> 0 | K9: =+COUNTIF($H27:$Q27,"Empatado") -> 1 | N9: =+COUNTIF($H27:$Q27,"Perdido") -> 2 | Q9: =+SUM(H9:N9) -> 3
G10: 2020 | H10: =+COUNTIF($H28:$Q28,"Ganado") -> 1 | K10: =+COUNTIF($H28:$Q28,"Empatado") -> 2 | N10: =+COUNTIF($H28:$Q28,"Perdido") -> 0 | Q10: =+SUM(H10:N10) -> 3
C11: Total Partidos Disputados | D11: =+SUM(D12:D14) -> 36 | E11: % | G11: 2021 | H11: =+COUNTIF($H29:$Q29,"Ganado") -> 1 | K11: =+COUNTIF($H29:$Q29,"Empatado") -> 0 | N11: =+COUNTIF($H29:$Q29,"Perdido") -> 2 | Q11: =+SUM(H11:N11) -> 3
C12: Ganados | D12: =+D17+D22+D27 -> 16 | E12: =+D12/D$11 -> 0.44444444 | G12: 2022 | H12: =+COUNTIF($H30:$Q30,"Ganado") -> 2 | K12: =+COUNTIF($H30:$Q30,"Empatado") -> 0 | N12: =+COUNTIF($H30:$Q30,"Perdido") -> 1 | Q12: =+SUM(H12:N12) -> 3
C13: Empatados | D13: =+D18+D23+D28 -> 5 | E13: =+D13/D$11 -> 0.13888889 | G13: 2023 | H13: =+COUNTIF($H31:$Q31,"Ganado") -> 1 | K13: =+COUNTIF($H31:$Q31,"Empatado") -> 0 | N13: =+COUNTIF($H31:$Q31,"Perdido") -> 2 | Q13: =+SUM(H13:N13) -> 3
C14: Perdidos | D14: =+D19+D24+D29 -> 15 | E14: =+D14/D$11 -> 0.41666667 | G14: 2024 | H14: =+COUNTIF($H32:$Q32,"Ganado") -> 2 | K14: =+COUNTIF($H32:$Q32,"Empatado") -> 0 | N14: =+COUNTIF($H32:$Q32,"Perdido") -> 1 | Q14: =+SUM(H14:N14) -> 3
G15: 2025 | H15: =+COUNTIF($H33:$Q33,"Ganado") -> 3 | K15: =+COUNTIF($H33:$Q33,"Empatado") -> 0 | N15: =+COUNTIF($H33:$Q33,"Perdido") -> 0 | Q15: =+SUM(H15:N15) -> 3
C16: Fourball Disputados | D16: =+SUM(D17:D19) -> 12 | E16: % | G16: Resultado Total | H16: =SUM(H4:H11) -> 8 | K16: =SUM(K4:K11) -> 5 | N16: =SUM(N4:N11) -> 11 | Q16: =SUM(Q4:Q15) -> 36
C17: Ganado | D17: =+COUNTIF($I$21:$I$33,"Ganado") -> 8 | E17: =+D17/D$16 -> 0.66666667
C18: Empatados | D18: =+COUNTIF($I$21:$I$33,"Empatado") -> 2 | E18: =+D18/D$16 -> 0.16666667 | G18: Puntos | H18: Fourball | I18: Resultado | J18: Enfrentamiento | K18: Greensome | L18: Resultado | M18: Enfrentamiento | N18: Singles | O18: Resultado | P18: Enfrentamiento | Q18: Total
C19: Perdidos | D19: =+COUNTIF($I$21:$I$33,"Perdido") -> 2 | E19: =+D19/D$16 -> 0.16666667 | G19: Puntos / Partido | H19: 0.5 | K19: 0.5 | N19: 1
G20: Máximo Disponible | H20: =H19*$E$6 -> 6 | K20: =K19*$E$6 -> 6 | N20: =N19*$E$6 -> 12 | Q20: =+SUM(H20:N20) -> 24
C21: Greesome Disputados | D21: =+SUM(D22:D24) -> 12 | E21: % | G21: 2013 | Q21: =+H21+K21+N21 -> 0
C22: Ganados | D22: =+COUNTIF($L$21:$L$33,"Ganado") -> 4 | E22: =+D22/D$21 -> 0.33333333 | G22: =+G21+1 -> 2014 | H22: 0 | I22: =+IF(H22=0.5,"Ganado",IF(H22=0.25,"Empatado",IF(H22<0.25,"Perdido"))) -> Perdido | J22: Diego - Herrero VS Dore - Cas | K22: 0.5 | L22: =+IF(K22=0.5,"Ganado",IF(K22=0.25,"Empatado",IF(K22<0.25,"Perdido"))) -> Ganado | M22: Diego - Herrero VS Dore - Cas | N22: 1 | O22: =+IF(N22=1,"Ganado",IF(N22=0.5,"Empatado",IF(N22<0.5,"Perdido"))) -> Ganado | P22: Merello | Q22: =+H22+K22+N22 -> 1.5
C23: Empatados | D23: =+COUNTIF($L$21:$L$33,"Empatado") -> 2 | E23: =+D23/D$21 -> 0.16666667 | G23: =+G22+1 -> 2015 | H23: 0.25 | I23: =+IF(H23=0.5,"Ganado",IF(H23=0.25,"Empatado",IF(H23<0.25,"Perdido"))) -> Empatado | J23: Diego - Herrero VS Prieto - Blasfi | K23: 0.25 | L23: =+IF(K23=0.5,"Ganado",IF(K23=0.25,"Empatado",IF(K23<0.25,"Perdido"))) -> Empatado | M23: Diego - Herrero VS Prieto - Blasfi | N23: 0 | O23: =+IF(N23=1,"Ganado",IF(N23=0.5,"Empatado",IF(N23<0.5,"Perdido"))) -> Perdido | P23: Prieto | Q23: =+H23+K23+N23 -> 0.5
C24: Perdidos | D24: =+COUNTIF($L$21:$L$33,"Perdido") -> 6 | E24: =+D24/D$21 -> 0.5 | G24: =+G23+1 -> 2016 | H24: 0.5 | I24: =+IF(H24=0.5,"Ganado",IF(H24=0.25,"Empatado",IF(H24<0.25,"Perdido"))) -> Ganado | J24: Diego - Nacho VS Alon - Prieto | K24: 0 | L24: =+IF(K24=0.5,"Ganado",IF(K24=0.25,"Empatado",IF(K24<0.25,"Perdido"))) -> Perdido | M24: Diego - Nacho VS Alon - Prieto | N24: 0 | O24: =+IF(N24=1,"Ganado",IF(N24=0.5,"Empatado",IF(N24<0.5,"Perdido"))) -> Perdido | P24: Bugo | Q24: =+H24+K24+N24 -> 0.5
G25: 2017 | H25: 0.5 | I25: =+IF(H25=0.5,"Ganado",IF(H25=0.25,"Empatado",IF(H25<0.25,"Perdido"))) -> Ganado | J25: Diego - Marcos VS Prieto - Castejas | K25: 0 | L25: =+IF(K25=0.5,"Ganado",IF(K25=0.25,"Empatado",IF(K25<0.25,"Perdido"))) -> Perdido | M25: Diego - Marcos VS Prieto - Castejas | N25: 1 | O25: =+IF(N25=1,"Ganado",IF(N25=0.5,"Empatado",IF(N25<0.5,"Perdido"))) -> Ganado | P25: Agus | Q25: =+H25+K25+N25 -> 1.5
C26: Individuales Disputados | D26: =+SUM(D27:D29) -> 12 | E26: % | G26: 2018 | H26: 0 | I26: =+IF(H26=0.5,"Ganado",IF(H26=0.25,"Empatado",IF(H26<0.25,"Perdido"))) -> Perdido | J26: Diego - Pedro VS Dore - Blasfi | K26: 0 | L26: =+IF(K26=0.5,"Ganado",IF(K26=0.25,"Empatado",IF(K26<0.25,"Perdido"))) -> Perdido | M26: Diego - Pedro VS Dore - Blasfi | N26: 1 | O26: =+IF(N26=1,"Ganado",IF(N26=0.5,"Empatado",IF(N26<0.5,"Perdido"))) -> Ganado | P26: Agus | Q26: =+H26+K26+N26 -> 1
C27: Ganados | D27: =+COUNTIF($O$21:$O$33,"Ganado") -> 4 | E27: =+D27/D$26 -> 0.33333333 | G27: 2019 | H27: 0.25 | I27: =+IF(H27=0.5,"Ganado",IF(H27=0.25,"Empatado",IF(H27<0.25,"Perdido"))) -> Empatado | J27: Marcos- Diego VS Castejas Prieto | K27: 0 | L27: =+IF(K27=0.5,"Ganado",IF(K27=0.25,"Empatado",IF(K27<0.25,"Perdido"))) -> Perdido | M27: Marcos- Diego VS Castejas Prieto | N27: 0 | O27: =+IF(N27=1,"Ganado",IF(N27=0.5,"Empatado",IF(N27<0.5,"Perdido"))) -> Perdido | P27: Castejas | Q27: =+H27+K27+N27 -> 0.25
C28: Empatados | D28: =+COUNTIF($O$21:$O$33,"Empatado") -> 1 | E28: =+D28/D$26 -> 0.083333333 | G28: 2020 | H28: 0.5 | I28: =+IF(H28=0.5,"Ganado",IF(H28=0.25,"Empatado",IF(H28<0.25,"Perdido"))) -> Ganado | J28: Diego Jaki - VS Jaime - Béjar | K28: 0.25 | L28: =+IF(K28=0.5,"Ganado",IF(K28=0.25,"Empatado",IF(K28<0.25,"Perdido"))) -> Empatado | M28: Diego Jaki - VS Jaime - Béjar | N28: 0.5 | O28: =+IF(N28=1,"Ganado",IF(N28=0.5,"Empatado",IF(N28<0.5,"Perdido"))) -> Empatado | P28: Blas | Q28: =+H28+K28+N28 -> 1.25
C29: Perdidos | D29: =+COUNTIF($O$21:$O$33,"Perdido") -> 7 | E29: =+D29/D$26 -> 0.58333333 | G29: 2021 | H29: 0.5 | I29: =+IF(H29=0.5,"Ganado",IF(H29=0.25,"Empatado",IF(H29<0.25,"Perdido"))) -> Ganado | J29: Diego-Pedro VS Alon-Nico | K29: 0 | L29: =+IF(K29=0.5,"Ganado",IF(K29=0.25,"Empatado",IF(K29<0.25,"Perdido"))) -> Perdido | M29: Diego-Pedro VS Alon-Nico | N29: 0 | O29: =+IF(N29=1,"Ganado",IF(N29=0.5,"Empatado",IF(N29<0.5,"Perdido"))) -> Perdido | P29: Bugo | Q29: =+H29+K29+N29 -> 0.5
G30: 2022 | H30: 0.5 | I30: =+IF(H30=0.5,"Ganado",IF(H30=0.25,"Empatado",IF(H30<0.25,"Perdido"))) -> Ganado | J30: Diego-Marcos VS Béjar-Juanma | K30: 0.5 | L30: =+IF(K30=0.5,"Ganado",IF(K30=0.25,"Empatado",IF(K30<0.25,"Perdido"))) -> Ganado | M30: Diego-Marcos VS Béjar-Juanma | N30: 0 | O30: =+IF(N30=1,"Ganado",IF(N30=0.5,"Empatado",IF(N30<0.5,"Perdido"))) -> Perdido | P30: Alon | Q30: =+H30+K30+N30 -> 1
G31: 2023 | H31: 0.5 | I31: =+IF(H31=0.5,"Ganado",IF(H31=0.25,"Empatado",IF(H31<0.25,"Perdido"))) -> Ganado | J31: Diego Nacho VS Pradas Béjar | K31: 0 | L31: =+IF(K31=0.5,"Ganado",IF(K31=0.25,"Empatado",IF(K31<0.25,"Perdido"))) -> Perdido | M31: Diego Nacho VS Pradas Béjar | N31: 0 | O31: =+IF(N31=1,"Ganado",IF(N31=0.5,"Empatado",IF(N31<0.5,"Perdido"))) -> Perdido | P31: Bugo | Q31: =+H31+K31+N31 -> 0.5
G32: 2024 | H32: 0.5 | I32: =+IF(H32=0.5,"Ganado",IF(H32=0.25,"Empatado",IF(H32<0.25,"Perdido"))) -> Ganado | J32: Diego Pedro VS Béjar Pradas | K32: 0.5 | L32: =+IF(K32=0.5,"Ganado",IF(K32=0.25,"Empatado",IF(K32<0.25,"Perdido"))) -> Ganado | M32: Diego Pedro VS Béjar Pradas | N32: 0 | O32: =+IF(N32=1,"Ganado",IF(N32=0.5,"Empatado",IF(N32<0.5,"Perdido"))) -> Perdido | P32: Nico | Q32: =+H32+K32+N32 -> 1
G33: 2025 | H33: 0.5 | I33: =+IF(H33=0.5,"Ganado",IF(H33=0.25,"Empatado",IF(H33<0.25,"Perdido"))) -> Ganado | J33: Diego Pedro VS Agus Juanma | K33: 0.5 | L33: =+IF(K33=0.5,"Ganado",IF(K33=0.25,"Empatado",IF(K33<0.25,"Perdido"))) -> Ganado | M33: Diego Pedro VS Agus Juanma | N33: 1 | O33: =+IF(N33=1,"Ganado",IF(N33=0.5,"Empatado",IF(N33<0.5,"Perdido"))) -> Ganado | P33: Merello | Q33: =+H33+K33+N33 -> 2
G34: Total | H34: =SUM(H22:H33) -> 4.5 | K34: =SUM(K22:K33) -> 2.5 | N34: =SUM(N21:N33) -> 4.5 | Q34: =SUM(Q21:Q33) -> 11.5

Sheet Fertxo
C3: Team | E3: Lobos | G3: Partidos | H3: Ganados | K3: Empatados | N3: Perdidos | Q3: Total
C4: Nombre | E4: Fertxo | G4: 2013 | H4: =+COUNTIF($H21:$Q21,"Ganado") -> 1 | K4: =+COUNTIF($H21:$Q21,"Empatado") -> 0 | N4: =+COUNTIF($H21:$Q21,"Perdido") -> 2 | Q4: =+SUM(H4:N4) -> 3
G5: 2014 | H5: =+COUNTIF($H22:$Q22,"Ganado") -> 1 | K5: =+COUNTIF($H22:$Q22,"Empatado") -> 1 | N5: =+COUNTIF($H22:$Q22,"Perdido") -> 1 | Q5: =+SUM(H5:N5) -> 3
C6: Total Participaciones | E6: =+COUNT(G4:G15) -> 12 | G6: 2016 | H6: =+COUNTIF($H24:$Q24,"Ganado") -> 0 | K6: =+COUNTIF($H24:$Q24,"Empatado") -> 1 | N6: =+COUNTIF($H24:$Q24,"Perdido") -> 2 | Q6: =+SUM(H6:N6) -> 3
C7: Puntos Disputados | E7: =+E6*2 -> 24 | G7: 2017 | H7: =+COUNTIF($H25:$Q25,"Ganado") -> 0 | K7: =+COUNTIF($H25:$Q25,"Empatado") -> 1 | N7: =+COUNTIF($H25:$Q25,"Perdido") -> 2 | Q7: =+SUM(H7:N7) -> 3
C8: Puntos Aportados | E8: =+Q34 -> 10 | G8: 2018 | H8: =+COUNTIF($H26:$Q26,"Ganado") -> 1 | K8: =+COUNTIF($H26:$Q26,"Empatado") -> 0 | N8: =+COUNTIF($H26:$Q26,"Perdido") -> 2 | Q8: =+SUM(H8:N8) -> 3
C9: Porcentaje Puntos | E9: =+E8/E7 -> 0.41666667 | G9: 2019 | H9: =+COUNTIF($H27:$Q27,"Ganado") -> 2 | K9: =+COUNTIF($H27:$Q27,"Empatado") -> 0 | N9: =+COUNTIF($H27:$Q27,"Perdido") -> 1 | Q9: =+SUM(H9:N9) -> 3
G10: 2020 | H10: =+COUNTIF($H28:$Q28,"Ganado") -> 0 | K10: =+COUNTIF($H28:$Q28,"Empatado") -> 1 | N10: =+COUNTIF($H28:$Q28,"Perdido") -> 2 | Q10: =+SUM(H10:N10) -> 3
C11: Total Partidos Disputados | D11: =+SUM(D12:D14) -> 36 | E11: % | G11: 2021 | H11: =+COUNTIF($H29:$Q29,"Ganado") -> 2 | K11: =+COUNTIF($H29:$Q29,"Empatado") -> 0 | N11: =+COUNTIF($H29:$Q29,"Perdido") -> 1 | Q11: =+SUM(H11:N11) -> 3
C12: Ganados | D12: =+D17+D22+D27 -> 11 | E12: =+D12/D$11 -> 0.30555556 | G12: 2022 | H12: =+COUNTIF($H30:$Q30,"Ganado") -> 1 | K12: =+COUNTIF($H30:$Q30,"Empatado") -> 0 | N12: =+COUNTIF($H30:$Q30,"Perdido") -> 2 | Q12: =+SUM(H12:N12) -> 3
C13: Empatados | D13: =+D18+D23+D28 -> 8 | E13: =+D13/D$11 -> 0.22222222 | G13: 2023 | H13: =+COUNTIF($H31:$Q31,"Ganado") -> 0 | K13: =+COUNTIF($H31:$Q31,"Empatado") -> 2 | N13: =+COUNTIF($H31:$Q31,"Perdido") -> 1 | Q13: =+SUM(H13:N13) -> 3
C14: Perdidos | D14: =+D19+D24+D29 -> 17 | E14: =+D14/D$11 -> 0.47222222 | G14: 2024 | H14: =+COUNTIF($H32:$Q32,"Ganado") -> 3 | K14: =+COUNTIF($H32:$Q32,"Empatado") -> 0 | N14: =+COUNTIF($H32:$Q32,"Perdido") -> 0 | Q14: =+SUM(H14:N14) -> 3
G15: 2025 | H15: =+COUNTIF($H33:$Q33,"Ganado") -> 0 | K15: =+COUNTIF($H33:$Q33,"Empatado") -> 2 | N15: =+COUNTIF($H33:$Q33,"Perdido") -> 1 | Q15: =+SUM(H15:N15) -> 3
C16: Fourball Disputados | D16: =+SUM(D17:D19) -> 12 | E16: % | G16: Resultado Total | H16: =+SUM(H4:H15) -> 11 | K16: =+SUM(K4:K15) -> 8 | N16: =+SUM(N4:N15) -> 17 | Q16: =SUM(Q4:Q15) -> 36
C17: Ganado | D17: =+COUNTIF($I$21:$I$33,"Ganado") -> 4 | E17: =+D17/D$16 -> 0.33333333
C18: Empatados | D18: =+COUNTIF($I$21:$I$33,"Empatado") -> 3 | E18: =+D18/D$16 -> 0.25 | G18: Puntos | H18: Fourball | I18: Resultado | J18: Enfrentamiento | K18: Greensome | L18: Resultado | M18: Enfrentamiento | N18: Singles | O18: Resultado | P18: Enfrentamiento | Q18: Total
C19: Perdidos | D19: =+COUNTIF($I$21:$I$33,"Perdido") -> 5 | E19: =+D19/D$16 -> 0.41666667 | G19: Puntos / Partido | H19: 0.5 | K19: 0.5 | N19: 1
G20: Máximo Disponible | H20: =H19*$E$6 -> 6 | K20: =K19*$E$6 -> 6 | N20: =N19*$E$6 -> 12 | Q20: =+SUM(H20:N20) -> 24
C21: Greesome Disputados | D21: =+SUM(D22:D24) -> 12 | E21: % | G21: 2013 | H21: 0 | I21: =+IF(H21=0.5,"Ganado",IF(H21=0.25,"Empatado",IF(H21<0.25,"Perdido"))) -> Perdido | J21: Fertxo - Juan VS Nico - Bugo | K21: 0.5 | L21: =+IF(K21=0.5,"Ganado",IF(K21=0.25,"Empatado",IF(K21<0.25,"Perdido"))) -> Ganado | M21: Fertxo - Juan VS Nico - Bugo | N21: 0 | O21: =+IF(N21=1,"Ganado",IF(N21=0.5,"Empatado",IF(N21<0.5,"Perdido"))) -> Perdido | P21: Blasfi | Q21: =+H21+K21+N21 -> 0.5
C22: Ganados | D22: =+COUNTIF($L$21:$L$33,"Ganado") -> 2 | E22: =+D22/D$21 -> 0.16666667 | G22: =+G21+1 -> 2014 | H22: 0 | I22: =+IF(H22=0.5,"Ganado",IF(H22=0.25,"Empatado",IF(H22<0.25,"Perdido"))) -> Perdido | J22: Fertxo - Juan VS Blasfi - Merello | K22: 0.25 | L22: =+IF(K22=0.5,"Ganado",IF(K22=0.25,"Empatado",IF(K22<0.25,"Perdido"))) -> Empatado | M22: Fertxo - Juan VS Blasfi - Merello | N22: 1 | O22: =+IF(N22=1,"Ganado",IF(N22=0.5,"Empatado",IF(N22<0.5,"Perdido"))) -> Ganado | P22: Nico | Q22: =+H22+K22+N22 -> 1.25
C23: Empatados | D23: =+COUNTIF($L$21:$L$33,"Empatado") -> 5 | E23: =+D23/D$21 -> 0.41666667 | G23: =+G22+1 -> 2015 | Q23: =+H23+K23+N23 -> 0
C24: Perdidos | D24: =+COUNTIF($L$21:$L$33,"Perdido") -> 5 | E24: =+D24/D$21 -> 0.41666667 | G24: =+G23+1 -> 2016 | H24: 0.25 | I24: =+IF(H24=0.5,"Ganado",IF(H24=0.25,"Empatado",IF(H24<0.25,"Perdido"))) -> Empatado | J24: Fertxo - Herrero VS Dore - Castejas | K24: 0 | L24: =+IF(K24=0.5,"Ganado",IF(K24=0.25,"Empatado",IF(K24<0.25,"Perdido"))) -> Perdido | M24: Fertxo - Herrero VS Dore - Castejas | N24: 0 | O24: =+IF(N24=1,"Ganado",IF(N24=0.5,"Empatado",IF(N24<0.5,"Perdido"))) -> Perdido | P24: Nico | Q24: =+H24+K24+N24 -> 0.25
G25: 2017 | H25: 0 | I25: =+IF(H25=0.5,"Ganado",IF(H25=0.25,"Empatado",IF(H25<0.25,"Perdido"))) -> Perdido | J25: Fertxo - Armando VS Bugo - Blasfi | K25: 0.25 | L25: =+IF(K25=0.5,"Ganado",IF(K25=0.25,"Empatado",IF(K25<0.25,"Perdido"))) -> Empatado | M25: Fertxo - Armando VS Bugo - Blasfi | N25: 0 | O25: =+IF(N25=1,"Ganado",IF(N25=0.5,"Empatado",IF(N25<0.5,"Perdido"))) -> Perdido | P25: Bugo | Q25: =+H25+K25+N25 -> 0.25
C26: Individuales Disputados | D26: =+SUM(D27:D29) -> 12 | E26: % | G26: 2018 | H26: 0.5 | I26: =+IF(H26=0.5,"Ganado",IF(H26=0.25,"Empatado",IF(H26<0.25,"Perdido"))) -> Ganado | J26: Fertxo - Estanis VS Bugo - Jaime | K26: 0 | L26: =+IF(K26=0.5,"Ganado",IF(K26=0.25,"Empatado",IF(K26<0.25,"Perdido"))) -> Perdido | M26: Fertxo - Estanis VS Bugo - Jaime | N26: 0 | O26: =+IF(N26=1,"Ganado",IF(N26=0.5,"Empatado",IF(N26<0.5,"Perdido"))) -> Perdido | P26: Nico | Q26: =+H26+K26+N26 -> 0.5
C27: Ganados | D27: =+COUNTIF($O$21:$O$33,"Ganado") -> 5 | E27: =+D27/D$26 -> 0.41666667 | G27: 2019 | H27: 0.5 | I27: =+IF(H27=0.5,"Ganado",IF(H27=0.25,"Empatado",IF(H27<0.25,"Perdido"))) -> Ganado | J27: Fertxo-Pedro VS Bugo-Jaime | K27: 0 | L27: =+IF(K27=0.5,"Ganado",IF(K27=0.25,"Empatado",IF(K27<0.25,"Perdido"))) -> Perdido | M27: Fertxo-Pedro VS Bugo-Jaime | N27: 1 | O27: =+IF(N27=1,"Ganado",IF(N27=0.5,"Empatado",IF(N27<0.5,"Perdido"))) -> Ganado | P27: Agus | Q27: =+H27+K27+N27 -> 1.5
C28: Empatados | D28: =+COUNTIF($O$21:$O$33,"Empatado") -> 0 | E28: =+D28/D$26 -> 0 | G28: 2020 | H28: 0 | I28: =+IF(H28=0.5,"Ganado",IF(H28=0.25,"Empatado",IF(H28<0.25,"Perdido"))) -> Perdido | J28: Fertxo-Marcos- VS Alon Nico | K28: 0.25 | L28: =+IF(K28=0.5,"Ganado",IF(K28=0.25,"Empatado",IF(K28<0.25,"Perdido"))) -> Empatado | M28: Fertxo-Marcos- VS Alon Nico | N28: 0 | O28: =+IF(N28=1,"Ganado",IF(N28=0.5,"Empatado",IF(N28<0.5,"Perdido"))) -> Perdido | P28: Castejas | Q28: =+H28+K28+N28 -> 0.25
C29: Perdidos | D29: =+COUNTIF($O$21:$O$33,"Perdido") -> 7 | E29: =+D29/D$26 -> 0.58333333 | G29: 2021 | H29: 0.5 | I29: =+IF(H29=0.5,"Ganado",IF(H29=0.25,"Empatado",IF(H29<0.25,"Perdido"))) -> Ganado | J29: Fertxo Jido VS - Bugo Nano | K29: 0 | L29: =+IF(K29=0.5,"Ganado",IF(K29=0.25,"Empatado",IF(K29<0.25,"Perdido"))) -> Perdido | M29: Fertxo Jido VS - Bugo Nano | N29: 1 | O29: =+IF(N29=1,"Ganado",IF(N29=0.5,"Empatado",IF(N29<0.5,"Perdido"))) -> Ganado | P29: Nano | Q29: =+H29+K29+N29 -> 1.5
G30: 2022 | H30: 0 | I30: =+IF(H30=0.5,"Ganado",IF(H30=0.25,"Empatado",IF(H30<0.25,"Perdido"))) -> Perdido | J30: Fertxo-Nacho VS Dore-Jaime | K30: 0 | L30: =+IF(K30=0.5,"Ganado",IF(K30=0.25,"Empatado",IF(K30<0.25,"Perdido"))) -> Perdido | M30: Fertxo-Nacho VS Dore-Jaime | N30: 1 | O30: =+IF(N30=1,"Ganado",IF(N30=0.5,"Empatado",IF(N30<0.5,"Perdido"))) -> Ganado | P30: Pelete | Q30: =+H30+K30+N30 -> 1
G31: 2023 | H31: 0.25 | I31: =+IF(H31=0.5,"Ganado",IF(H31=0.25,"Empatado",IF(H31<0.25,"Perdido"))) -> Empatado | J31: Fertxo Marcos VS Bugo Nico | K31: 0.25 | L31: =+IF(K31=0.5,"Ganado",IF(K31=0.25,"Empatado",IF(K31<0.25,"Perdido"))) -> Empatado | M31: Fertxo Marcos VS Bugo Nico | N31: 0 | O31: =+IF(N31=1,"Ganado",IF(N31=0.5,"Empatado",IF(N31<0.5,"Perdido"))) -> Perdido | P31: Agus | Q31: =+H31+K31+N31 -> 0.5
G32: 2024 | H32: 0.5 | I32: =+IF(H32=0.5,"Ganado",IF(H32=0.25,"Empatado",IF(H32<0.25,"Perdido"))) -> Ganado | J32: Fertxo Nacho VS Prieto Castejas | K32: 0.5 | L32: =+IF(K32=0.5,"Ganado",IF(K32=0.25,"Empatado",IF(K32<0.25,"Perdido"))) -> Ganado | M32: Fertxo Nacho VS Prieto Castejas | N32: 1 | O32: =+IF(N32=1,"Ganado",IF(N32=0.5,"Empatado",IF(N32<0.5,"Perdido"))) -> Ganado | P32: Castejas | Q32: =+H32+K32+N32 -> 2
G33: 2025 | H33: 0.25 | I33: =+IF(H33=0.5,"Ganado",IF(H33=0.25,"Empatado",IF(H33<0.25,"Perdido"))) -> Empatado | J33: Fertxo Nacho VS Blas Béjar | K33: 0.25 | L33: =+IF(K33=0.5,"Ganado",IF(K33=0.25,"Empatado",IF(K33<0.25,"Perdido"))) -> Empatado | M33: Fertxo Nacho VS Blas Béjar | N33: 0 | O33: =+IF(N33=1,"Ganado",IF(N33=0.5,"Empatado",IF(N33<0.5,"Perdido"))) -> Perdido | P33: Prieto | Q33: =+H33+K33+N33 -> 0.5
G34: Total | H34: =SUM(H21:H33) -> 2.75 | K34: =SUM(K21:K33) -> 2.25 | N34: =SUM(N21:N33) -> 5 | Q34: =SUM(Q21:Q33) -> 10

Sheet Nacho
C4: Team | E4: Lobos | G4: Partidos | H4: Ganados | K4: Empatados | N4: Perdidos | Q4: Total
C5: Nombre | E5: Nacho | G5: 2015 | H5: =+COUNTIF($H23:$Q23,"Ganado") -> 0 | K5: =+COUNTIF($H23:$Q23,"Empatado") -> 2 | N5: =+COUNTIF($H23:$Q23,"Perdido") -> 1 | Q5: =+SUM(H5:N5) -> 3
G6: 2016 | H6: =+COUNTIF($H24:$Q24,"Ganado") -> 1 | K6: =+COUNTIF($H24:$Q24,"Empatado") -> 0 | N6: =+COUNTIF($H24:$Q24,"Perdido") -> 2 | Q6: =+SUM(H6:N6) -> 3
C7: Total Participaciones | E7: =+COUNT(G5:G15) -> 11 | G7: 2017 | H7: =+COUNTIF($H25:$Q25,"Ganado") -> 0 | K7: =+COUNTIF($H25:$Q25,"Empatado") -> 0 | N7: =+COUNTIF($H25:$Q25,"Perdido") -> 3 | Q7: =+SUM(H7:N7) -> 3
C8: Puntos Disputados | E8: =+E7*2 -> 22 | G8: 2018 | H8: =+COUNTIF($H26:$Q26,"Ganado") -> 1 | K8: =+COUNTIF($H26:$Q26,"Empatado") -> 0 | N8: =+COUNTIF($H26:$Q26,"Perdido") -> 2 | Q8: =+SUM(H8:N8) -> 3
C9: Puntos Aportados | E9: =+Q34 -> 5 | G9: 2019 | H9: =+COUNTIF($H27:$Q27,"Ganado") -> 0 | K9: =+COUNTIF($H27:$Q27,"Empatado") -> 1 | N9: =+COUNTIF($H27:$Q27,"Perdido") -> 2 | Q9: =+SUM(H9:N9) -> 3
C10: Porcentaje Puntos | E10: =+E9/E8 -> 0.22727273 | G10: 2020 | H10: =+COUNTIF($H28:$Q28,"Ganado") -> 1 | K10: =+COUNTIF($H28:$Q28,"Empatado") -> 0 | N10: =+COUNTIF($H28:$Q28,"Perdido") -> 2 | Q10: =+SUM(H10:N10) -> 3
G11: 2021 | H11: =+COUNTIF($H29:$Q29,"Ganado") -> 0 | K11: =+COUNTIF($H29:$Q29,"Empatado") -> 0 | N11: =+COUNTIF($H29:$Q29,"Perdido") -> 3 | Q11: =+SUM(H11:N11) -> 3
C12: Total Partidos Disputados | D12: =+SUM(D13:D15) -> 33 | E12: % | G12: 2022 | H12: =+COUNTIF($H30:$Q30,"Ganado") -> 0 | K12: =+COUNTIF($H30:$Q30,"Empatado") -> 1 | N12: =+COUNTIF($H30:$Q30,"Perdido") -> 2 | Q12: =+SUM(H12:N12) -> 3
C13: Ganados | D13: =+D18+D23+D28 -> 6 | E13: =+D13/D$12 -> 0.18181818 | G13: 2023 | H13: =+COUNTIF($H31:$Q31,"Ganado") -> 1 | K13: =+COUNTIF($H31:$Q31,"Empatado") -> 0 | N13: =+COUNTIF($H31:$Q31,"Perdido") -> 2 | Q13: =+SUM(H13:N13) -> 3
C14: Empatados | D14: =+D19+D24+D29 -> 6 | E14: =+D14/D$12 -> 0.18181818 | G14: 2024 | H14: =+COUNTIF($H32:$Q32,"Ganado") -> 2 | K14: =+COUNTIF($H32:$Q32,"Empatado") -> 0 | N14: =+COUNTIF($H32:$Q32,"Perdido") -> 1 | Q14: =+SUM(H14:N14) -> 3
C15: Perdidos | D15: =+D20+D25+D30 -> 21 | E15: =+D15/D$12 -> 0.63636364 | G15: 2025 | H15: =+COUNTIF($H33:$Q33,"Ganado") -> 0 | K15: =+COUNTIF($H33:$Q33,"Empatado") -> 2 | N15: =+COUNTIF($H33:$Q33,"Perdido") -> 1 | Q15: =+SUM(H15:N15) -> 3
G16: Resultado Total | H16: =SUM(H5:H11) -> 3 | K16: =SUM(K5:K11) -> 3 | N16: =SUM(N5:N11) -> 15 | Q16: =SUM(Q5:Q15) -> 33
C17: Fourball Disputados | D17: =+SUM(D18:D20) -> 11 | E17: %
C18: Ganado | D18: =+COUNTIF($I$21:$I$33,"Ganado") -> 5 | E18: =+D18/D$17 -> 0.45454545 | G18: Puntos | H18: Fourball | I18: Resultado | J18: Enfrentamiento | K18: Greensome | L18: Resultado | M18: Enfrentamiento | N18: Singles | O18: Resultado | P18: Enfrentamiento | Q18: Total
C19: Empatados | D19: =+COUNTIF($I$21:$I$33,"Empatado") -> 2 | E19: =+D19/D$17 -> 0.18181818 | G19: Puntos / Partido | H19: 0.5 | K19: 0.5 | N19: 1
C20: Perdidos | D20: =+COUNTIF($I$21:$I$33,"Perdido") -> 4 | E20: =+D20/D$17 -> 0.36363636 | G20: Máximo Disponible | H20: =H19*$E$7 -> 5.5 | K20: =K19*$E$7 -> 5.5 | N20: =N19*$E$7 -> 11 | Q20: =+SUM(H20:N20) -> 22
G21: 2013 | Q21: =+H21+K21+N21 -> 0
C22: Greesome Disputados | D22: =+SUM(D23:D25) -> 11 | E22: % | G22: =+G21+1 -> 2014 | Q22: =+H22+K22+N22 -> 0
C23: Ganados | D23: =+COUNTIF($L$21:$L$33,"Ganado") -> 1 | E23: =+D23/D$22 -> 0.090909091 | G23: =+G22+1 -> 2015 | H23: 0.25 | I23: =+IF(H23=0.5,"Ganado",IF(H23=0.25,"Empatado",IF(H23<0.25,"Perdido"))) -> Empatado | J23: Nacho - Juan VS Bugo - Alon | K23: 0.25 | L23: =+IF(K23=0.5,"Ganado",IF(K23=0.25,"Empatado",IF(K23<0.25,"Perdido"))) -> Empatado | M23: Nacho - Juan VS Bugo - Alon | N23: 0 | O23: =+IF(N23=1,"Ganado",IF(N23=0.5,"Empatado",IF(N23<0.5,"Perdido"))) -> Perdido | P23: Alon | Q23: =+H23+K23+N23 -> 0.5
C24: Empatados | D24: =+COUNTIF($L$21:$L$33,"Empatado") -> 2 | E24: =+D24/D$22 -> 0.18181818 | G24: =+G23+1 -> 2016 | H24: 0.5 | I24: =+IF(H24=0.5,"Ganado",IF(H24=0.25,"Empatado",IF(H24<0.25,"Perdido"))) -> Ganado | J24: Nacho - Diego VS Alon - Prieto | K24: 0 | L24: =+IF(K24=0.5,"Ganado",IF(K24=0.25,"Empatado",IF(K24<0.25,"Perdido"))) -> Perdido | M24: Nacho - Diego VS Alon - Prieto | N24: 0 | O24: =+IF(N24=1,"Ganado",IF(N24=0.5,"Empatado",IF(N24<0.5,"Perdido"))) -> Perdido | P24: Jaime | Q24: =+H24+K24+N24 -> 0.5
C25: Perdidos | D25: =+COUNTIF($L$21:$L$33,"Perdido") -> 8 | E25: =+D25/D$22 -> 0.72727273 | G25: 2017 | H25: 0 | I25: =+IF(H25=0.5,"Ganado",IF(H25=0.25,"Empatado",IF(H25<0.25,"Perdido"))) -> Perdido | J25: Nacho - Juan VS Jaime - Béjar | K25: 0 | L25: =+IF(K25=0.5,"Ganado",IF(K25=0.25,"Empatado",IF(K25<0.25,"Perdido"))) -> Perdido | M25: Nacho - Juan VS Jaime - Béjar | N25: 0 | O25: =+IF(N25=1,"Ganado",IF(N25=0.5,"Empatado",IF(N25<0.5,"Perdido"))) -> Perdido | P25: Alon | Q25: =+H25+K25+N25 -> 0
G26: 2018 | H26: 0.5 | I26: =+IF(H26=0.5,"Ganado",IF(H26=0.25,"Empatado",IF(H26<0.25,"Perdido"))) -> Ganado | J26: Nacho - Edwards VS Alon - Béjar | K26: 0 | L26: =+IF(K26=0.5,"Ganado",IF(K26=0.25,"Empatado",IF(K26<0.25,"Perdido"))) -> Perdido | M26: Nacho - Edwards VS Alon - Béjar | N26: 0 | O26: =+IF(N26=1,"Ganado",IF(N26=0.5,"Empatado",IF(N26<0.5,"Perdido"))) -> Perdido | P26: Alon | Q26: =+H26+K26+N26 -> 0.5
C27: Individuales Disputados | D27: =+SUM(D28:D30) -> 11 | E27: % | G27: 2019 | H27: 0 | I27: =+IF(H27=0.5,"Ganado",IF(H27=0.25,"Empatado",IF(H27<0.25,"Perdido"))) -> Perdido | J27: Nacho - Edwards VS Dore-Blas | K27: 0 | L27: =+IF(K27=0.5,"Ganado",IF(K27=0.25,"Empatado",IF(K27<0.25,"Perdido"))) -> Perdido | M27: Nacho - Edwards VS Alon - Béjar | N27: 0.5 | O27: =+IF(N27=1,"Ganado",IF(N27=0.5,"Empatado",IF(N27<0.5,"Perdido"))) -> Empatado | P27: Nico | Q27: =+H27+K27+N27 -> 0.5
C28: Ganados | D28: =+COUNTIF($O$21:$O$33,"Ganado") -> 0 | E28: =+D28/D$27 -> 0 | G28: 2020 | H28: 0.5 | I28: =+IF(H28=0.5,"Ganado",IF(H28=0.25,"Empatado",IF(H28<0.25,"Perdido"))) -> Ganado | J28: Nacho - Edwards VS Dore-Blas | K28: 0 | L28: =+IF(K28=0.5,"Ganado",IF(K28=0.25,"Empatado",IF(K28<0.25,"Perdido"))) -> Perdido | M28: Nacho - Edwards VS Dore-Blas | N28: 0 | O28: =+IF(N28=1,"Ganado",IF(N28=0.5,"Empatado",IF(N28<0.5,"Perdido"))) -> Perdido | P28: Alf Nico | Q28: =+H28+K28+N28 -> 0.5
C29: Empatados | D29: =+COUNTIF($O$21:$O$33,"Empatado") -> 2 | E29: =+D29/D$27 -> 0.18181818 | G29: 2021 | H29: 0 | I29: =+IF(H29=0.5,"Ganado",IF(H29=0.25,"Empatado",IF(H29<0.25,"Perdido"))) -> Perdido | J29: Nacho- P. Medina VS Blas Dore | K29: 0 | L29: =+IF(K29=0.5,"Ganado",IF(K29=0.25,"Empatado",IF(K29<0.25,"Perdido"))) -> Perdido | M29: Nacho P. Medina VS Blas Dore | N29: 0 | O29: =+IF(N29=1,"Ganado",IF(N29=0.5,"Empatado",IF(N29<0.5,"Perdido"))) -> Perdido | P29: Béjar | Q29: =+H29+K29+N29 -> 0
C30: Perdidos | D30: =+COUNTIF($O$21:$O$33,"Perdido") -> 9 | E30: =+D30/D$27 -> 0.81818182 | G30: 2022 | H30: 0 | I30: =+IF(H30=0.5,"Ganado",IF(H30=0.25,"Empatado",IF(H30<0.25,"Perdido"))) -> Perdido | J30: Nacho-Fertxo VS Dore-Jaime | K30: 0 | L30: =+IF(K30=0.5,"Ganado",IF(K30=0.25,"Empatado",IF(K30<0.25,"Perdido"))) -> Perdido | M30: Nacho-Fertxo VS Dore-Jaime | N30: 0.5 | O30: =+IF(N30=1,"Ganado",IF(N30=0.5,"Empatado",IF(N30<0.5,"Perdido"))) -> Empatado | P30: Juanma Melgarejo | Q30: =+H30+K30+N30 -> 0.5
G31: 2023 | H31: 0.5 | I31: =+IF(H31=0.5,"Ganado",IF(H31=0.25,"Empatado",IF(H31<0.25,"Perdido"))) -> Ganado | J31: Nacho Diego VS Pradas Béjar | K31: 0 | L31: =+IF(K31=0.5,"Ganado",IF(K31=0.25,"Empatado",IF(K31<0.25,"Perdido"))) -> Perdido | M31: Nacho Diego VS Pradas Béjar | N31: 0 | O31: =+IF(N31=1,"Ganado",IF(N31=0.5,"Empatado",IF(N31<0.5,"Perdido"))) -> Perdido | P31: Alon | Q31: =+H31+K31+N31 -> 0.5
G32: 2024 | H32: 0.5 | I32: =+IF(H32=0.5,"Ganado",IF(H32=0.25,"Empatado",IF(H32<0.25,"Perdido"))) -> Ganado | J32: Nacho Fertxo VS Prieto Castejas | K32: 0.5 | L32: =+IF(K32=0.5,"Ganado",IF(K32=0.25,"Empatado",IF(K32<0.25,"Perdido"))) -> Ganado | M32: Nacho Fertxo VS Prieto Castejas | N32: 0 | O32: =+IF(N32=1,"Ganado",IF(N32=0.5,"Empatado",IF(N32<0.5,"Perdido"))) -> Perdido | P32: Béjar | Q32: =+H32+K32+N32 -> 1
G33: 2025 | H33: 0.25 | I33: =+IF(H33=0.5,"Ganado",IF(H33=0.25,"Empatado",IF(H33<0.25,"Perdido"))) -> Empatado | J33: Fertxo Nacho VS Blas Béjar | K33: 0.25 | L33: =+IF(K33=0.5,"Ganado",IF(K33=0.25,"Empatado",IF(K33<0.25,"Perdido"))) -> Empatado | M33: Fertxo Nacho VS Blas Béjar | N33: 0 | O33: =+IF(N33=1,"Ganado",IF(N33=0.5,"Empatado",IF(N33<0.5,"Perdido"))) -> Perdido | P33: Rodrigo Cortés | Q33: =+H33+K33+N33 -> 0.5
G34: Total | H34: =SUM(H23:H33) -> 3 | K34: =SUM(K23:K33) -> 1 | N34: =SUM(N23:N33) -> 1 | Q34: =SUM(Q21:Q33) -> 5

Sheet Pedro
C2: Team | E2: Lobos | G2: Partidos | H2: Ganados | K2: Empatados | N2: Perdidos | Q2: Total
C3: Nombre | E3: Pedro | G3: 2013 | H3: =+COUNTIF($H21:$Q21,"Ganado") -> 3 | K3: =+COUNTIF($H21:$Q21,"Empatado") -> 0 | N3: =+COUNTIF($H21:$Q21,"Perdido") -> 0 | Q3: =+SUM(H3:N3) -> 3
G4: 2014 | H4: =+COUNTIF($H22:$Q22,"Ganado") -> 0 | K4: =+COUNTIF($H22:$Q22,"Empatado") -> 2 | N4: =+COUNTIF($H22:$Q22,"Perdido") -> 1 | Q4: =+SUM(H4:N4) -> 3
C5: Total Participaciones | E5: =+COUNT(G3:G14) -> 12 | G5: 2015 | H5: =+COUNTIF($H23:$Q23,"Ganado") -> 1 | K5: =+COUNTIF($H23:$Q23,"Empatado") -> 1 | N5: =+COUNTIF($H23:$Q23,"Perdido") -> 1 | Q5: =+SUM(H5:N5) -> 3
C6: Puntos Disputados | E6: =+E5*2 -> 24 | G6: 2016 | H6: =+COUNTIF($H24:$Q24,"Ganado") -> 0 | K6: =+COUNTIF($H24:$Q24,"Empatado") -> 0 | N6: =+COUNTIF($H24:$Q24,"Perdido") -> 3 | Q6: =+SUM(H6:N6) -> 3
C7: Puntos Aportados | E7: =+Q34 -> 11.75 | G7: 2017 | H7: =+COUNTIF($H25:$Q25,"Ganado") -> 1 | K7: =+COUNTIF($H25:$Q25,"Empatado") -> 1 | N7: =+COUNTIF($H25:$Q25,"Perdido") -> 1 | Q7: =+SUM(H7:N7) -> 3
C8: Porcentaje Puntos | E8: =+E7/E6 -> 0.48958333 | G8: 2018 | H8: =+COUNTIF($H26:$Q26,"Ganado") -> 0 | K8: =+COUNTIF($H26:$Q26,"Empatado") -> 0 | N8: =+COUNTIF($H26:$Q26,"Perdido") -> 3 | Q8: =+SUM(H8:N8) -> 3
G9: 2019 | H9: =+COUNTIF($H27:$Q27,"Ganado") -> 2 | K9: =+COUNTIF($H27:$Q27,"Empatado") -> 0 | N9: =+COUNTIF($H27:$Q27,"Perdido") -> 1 | Q9: =+SUM(H9:N9) -> 3
C10: Total Partidos Disputados | D10: =+SUM(D11:D13) -> 39 | E10: % | G10: 2020 | H10: =+COUNTIF($H28:$Q28,"Ganado") -> 0 | K10: =+COUNTIF($H28:$Q28,"Empatado") -> 2 | N10: =+COUNTIF($H28:$Q28,"Perdido") -> 1 | Q10: =+SUM(H10:N10) -> 3
C11: Ganados | D11: =+D16+D21+D26 -> 15 | E11: =+D11/D$10 -> 0.38461538 | G11: 2021 | H11: =+COUNTIF($H29:$Q29,"Ganado") -> 1 | K11: =+COUNTIF($H29:$Q29,"Empatado") -> 0 | N11: =+COUNTIF($H29:$Q29,"Perdido") -> 2 | Q11: =+SUM(H11:N11) -> 3
C12: Empatados | D12: =+D17+D22+D27 -> 7 | E12: =+D12/D$10 -> 0.17948718 | G12: 2022 | H12: =+COUNTIF($H30:$Q30,"Ganado") -> 1 | K12: =+COUNTIF($H30:$Q30,"Empatado") -> 1 | N12: =+COUNTIF($H30:$Q30,"Perdido") -> 1 | Q12: =+SUM(H12:N12) -> 3
C13: Perdidos | D13: =+D18+D23+D28 -> 17 | E13: =+D13/D$10 -> 0.43589744 | G13: 2023 | H13: =+COUNTIF($H31:$Q31,"Ganado") -> 1 | K13: =+COUNTIF($H31:$Q31,"Empatado") -> 0 | N13: =+COUNTIF($H31:$Q31,"Perdido") -> 2 | Q13: =+SUM(H13:N13) -> 3
G14: 2024 | H14: =+COUNTIF($H32:$Q32,"Ganado") -> 3 | K14: =+COUNTIF($H32:$Q32,"Empatado") -> 0 | N14: =+COUNTIF($H32:$Q32,"Perdido") -> 0 | Q14: =+SUM(H14:N14) -> 3
C15: Fourball Disputados | D15: =+SUM(D16:D18) -> 13 | E15: % | G15: 2025
C16: Ganado | D16: =+COUNTIF($I$21:$I$33,"Ganado") -> 6 | E16: =+D16/D$15 -> 0.46153846 | G16: Resultado Total | H16: =SUM(H3:H11) -> 8 | K16: =SUM(K3:K11) -> 6 | N16: =SUM(N3:N11) -> 13 | Q16: =SUM(Q3:Q15) -> 36
C17: Empatados | D17: =+COUNTIF($I$21:$I$33,"Empatado") -> 3 | E17: =+D17/D$15 -> 0.23076923
C18: Perdidos | D18: =+COUNTIF($I$21:$I$33,"Perdido") -> 4 | E18: =+D18/D$15 -> 0.30769231 | G18: Puntos | H18: Fourball | I18: Resultado | J18: Enfrentamiento | K18: Greensome | L18: Resultado | M18: Enfrentamiento | N18: Singles | O18: Resultado | P18: Enfrentamiento | Q18: Total
G19: Puntos / Partido | H19: 0.5 | K19: 0.5 | N19: 1
C20: Greesome Disputados | D20: =+SUM(D21:D23) -> 13 | E20: % | G20: Máximo Disponible | H20: =H19*$E$5 -> 6 | K20: =K19*$E$5 -> 6 | N20: =N19*$E$5 -> 12 | Q20: =+SUM(H20:N20) -> 24
C21: Ganados | D21: =+COUNTIF($L$21:$L$33,"Ganado") -> 4 | E21: =+D21/D$20 -> 0.30769231 | G21: 2013 | H21: 0.5 | I21: =+IF(H21=0.5,"Ganado",IF(H21=0.25,"Empatado",IF(H21<0.25,"Perdido"))) -> Ganado | J21: Pedro - Jaki Vs Blasfi - Cas | K21: 0.5 | L21: =+IF(K21=0.5,"Ganado",IF(K21=0.25,"Empatado",IF(K21<0.25,"Perdido"))) -> Ganado | M21: Pedro - Jaki Vs Blasfi - Cas | N21: 1 | O21: =+IF(N21=1,"Ganado",IF(N21=0.5,"Empatado",IF(N21<0.5,"Perdido"))) -> Ganado | P21: Castejas | Q21: =+H21+K21+N21 -> 2
C22: Empatados | D22: =+COUNTIF($L$21:$L$33,"Empatado") -> 4 | E22: =+D22/D$20 -> 0.30769231 | G22: =+G21+1 -> 2014 | H22: 0.25 | I22: =+IF(H22=0.5,"Ganado",IF(H22=0.25,"Empatado",IF(H22<0.25,"Perdido"))) -> Empatado | J22: Pedro - Jaki Vs Béjar-Nico | K22: 0.25 | L22: =+IF(K22=0.5,"Ganado",IF(K22=0.25,"Empatado",IF(K22<0.25,"Perdido"))) -> Empatado | M22: Pedro - Jaki Vs Béjar-Nico | N22: 0 | O22: =+IF(N22=1,"Ganado",IF(N22=0.5,"Empatado",IF(N22<0.5,"Perdido"))) -> Perdido | P22: Alon | Q22: =+H22+K22+N22 -> 0.5
C23: Perdidos | D23: =+COUNTIF($L$21:$L$33,"Perdido") -> 5 | E23: =+D23/D$20 -> 0.38461538 | G23: =+G22+1 -> 2015 | H23: 0.25 | I23: =+IF(H23=0.5,"Ganado",IF(H23=0.25,"Empatado",IF(H23<0.25,"Perdido"))) -> Empatado | J23: Pedro - Jaki Vs Béjar-Nico | K23: 0.5 | L23: =+IF(K23=0.5,"Ganado",IF(K23=0.25,"Empatado",IF(K23<0.25,"Perdido"))) -> Ganado | M23: Pedro - Jaki Vs Béjar-Nico | N23: 0 | O23: =+IF(N23=1,"Ganado",IF(N23=0.5,"Empatado",IF(N23<0.5,"Perdido"))) -> Perdido | P23: Dore | Q23: =+H23+K23+N23 -> 0.75
